2019-08-24 08:35:17,009 INFO : Microblog startup [in D:\ThunderDownload\Python_code\venv_test\app\__init__.py:42]
2019-08-24 09:11:30,737 INFO : Microblog startup [in D:\ThunderDownload\Python_code\venv_test\app\__init__.py:42]
2019-08-24 09:11:55,404 INFO : Microblog startup [in D:\ThunderDownload\Python_code\venv_test\app\__init__.py:42]
2019-08-24 09:12:22,761 INFO : Microblog startup [in D:\ThunderDownload\Python_code\venv_test\app\__init__.py:42]
2019-08-24 10:10:31,803 INFO : Microblog startup [in D:\ThunderDownload\Python_code\venv_test\app\__init__.py:42]
2019-08-24 10:10:46,606 INFO : Microblog startup [in D:\ThunderDownload\Python_code\venv_test\app\__init__.py:42]
2019-08-24 10:44:47,393 INFO : Microblog startup [in D:\ThunderDownload\Python_code\venv_test\app\__init__.py:42]
2019-08-24 10:45:00,829 ERROR : Exception on /index [GET] [in d:\thunderdownload\python_code\venv_test\ve1\lib\site-packages\flask\app.py:1891]
Traceback (most recent call last):
  File "d:\thunderdownload\python_code\venv_test\ve1\lib\site-packages\flask\app.py", line 2446, in wsgi_app
    response = self.full_dispatch_request()
  File "d:\thunderdownload\python_code\venv_test\ve1\lib\site-packages\flask\app.py", line 1951, in full_dispatch_request
    rv = self.handle_user_exception(e)
  File "d:\thunderdownload\python_code\venv_test\ve1\lib\site-packages\flask\app.py", line 1820, in handle_user_exception
    reraise(exc_type, exc_value, tb)
  File "d:\thunderdownload\python_code\venv_test\ve1\lib\site-packages\flask\_compat.py", line 39, in reraise
    raise value
  File "d:\thunderdownload\python_code\venv_test\ve1\lib\site-packages\flask\app.py", line 1949, in full_dispatch_request
    rv = self.dispatch_request()
  File "d:\thunderdownload\python_code\venv_test\ve1\lib\site-packages\flask\app.py", line 1935, in dispatch_request
    return self.view_functions[rule.endpoint](**req.view_args)
  File "d:\thunderdownload\python_code\venv_test\ve1\lib\site-packages\flask_login\utils.py", line 261, in decorated_view
    return func(*args, **kwargs)
  File "D:\ThunderDownload\Python_code\venv_test\app\routes.py", line 16, in index
    form = PostForm()
  File "d:\thunderdownload\python_code\venv_test\ve1\lib\site-packages\wtforms\form.py", line 212, in __call__
    return type.__call__(cls, *args, **kwargs)
  File "d:\thunderdownload\python_code\venv_test\ve1\lib\site-packages\flask_wtf\form.py", line 88, in __init__
    super(FlaskForm, self).__init__(formdata=formdata, **kwargs)
  File "d:\thunderdownload\python_code\venv_test\ve1\lib\site-packages\wtforms\form.py", line 272, in __init__
    super(Form, self).__init__(self._unbound_fields, meta=meta_obj, prefix=prefix)
  File "d:\thunderdownload\python_code\venv_test\ve1\lib\site-packages\wtforms\form.py", line 52, in __init__
    field = meta.bind_field(self, unbound_field, options)
  File "d:\thunderdownload\python_code\venv_test\ve1\lib\site-packages\wtforms\meta.py", line 27, in bind_field
    return unbound_field.bind(form=form, **options)
  File "d:\thunderdownload\python_code\venv_test\ve1\lib\site-packages\wtforms\fields\core.py", line 353, in bind
    return self.field_class(*self.args, **kw)
TypeError: __init__() got an unexpected keyword argument 'validatiors'
2019-08-24 10:46:09,023 INFO : Microblog startup [in D:\ThunderDownload\Python_code\venv_test\app\__init__.py:42]
2019-08-24 10:57:47,582 INFO : Microblog startup [in D:\ThunderDownload\Python_code\venv_test\app\__init__.py:42]
2019-08-24 10:57:57,160 ERROR : Exception on /index [GET] [in d:\thunderdownload\python_code\venv_test\ve1\lib\site-packages\flask\app.py:1891]
Traceback (most recent call last):
  File "d:\thunderdownload\python_code\venv_test\ve1\lib\site-packages\flask\app.py", line 2446, in wsgi_app
    response = self.full_dispatch_request()
  File "d:\thunderdownload\python_code\venv_test\ve1\lib\site-packages\flask\app.py", line 1951, in full_dispatch_request
    rv = self.handle_user_exception(e)
  File "d:\thunderdownload\python_code\venv_test\ve1\lib\site-packages\flask\app.py", line 1820, in handle_user_exception
    reraise(exc_type, exc_value, tb)
  File "d:\thunderdownload\python_code\venv_test\ve1\lib\site-packages\flask\_compat.py", line 39, in reraise
    raise value
  File "d:\thunderdownload\python_code\venv_test\ve1\lib\site-packages\flask\app.py", line 1949, in full_dispatch_request
    rv = self.dispatch_request()
  File "d:\thunderdownload\python_code\venv_test\ve1\lib\site-packages\flask\app.py", line 1935, in dispatch_request
    return self.view_functions[rule.endpoint](**req.view_args)
  File "d:\thunderdownload\python_code\venv_test\ve1\lib\site-packages\flask_login\utils.py", line 261, in decorated_view
    return func(*args, **kwargs)
  File "D:\ThunderDownload\Python_code\venv_test\app\routes.py", line 26, in index
    return render_template('index.html', title='Home', form= form, posts=posts)
  File "d:\thunderdownload\python_code\venv_test\ve1\lib\site-packages\flask\templating.py", line 140, in render_template
    ctx.app,
  File "d:\thunderdownload\python_code\venv_test\ve1\lib\site-packages\flask\templating.py", line 120, in _render
    rv = template.render(context)
  File "d:\thunderdownload\python_code\venv_test\ve1\lib\site-packages\jinja2\asyncsupport.py", line 76, in render
    return original_render(self, *args, **kwargs)
  File "d:\thunderdownload\python_code\venv_test\ve1\lib\site-packages\jinja2\environment.py", line 1008, in render
    return self.environment.handle_exception(exc_info, True)
  File "d:\thunderdownload\python_code\venv_test\ve1\lib\site-packages\jinja2\environment.py", line 780, in handle_exception
    reraise(exc_type, exc_value, tb)
  File "d:\thunderdownload\python_code\venv_test\ve1\lib\site-packages\jinja2\_compat.py", line 37, in reraise
    raise value.with_traceback(tb)
  File "D:\ThunderDownload\Python_code\venv_test\app\templates\index.html", line 1, in top-level template code
    {% extends "base.html" %}
  File "D:\ThunderDownload\Python_code\venv_test\app\templates\base.html", line 31, in top-level template code
    {% block content %}{% endblock %}
  File "D:\ThunderDownload\Python_code\venv_test\app\templates\index.html", line 18, in block "content"
    {% for post in posts %}
TypeError: 'Pagination' object is not iterable
2019-08-24 10:58:54,461 INFO : Microblog startup [in D:\ThunderDownload\Python_code\venv_test\app\__init__.py:42]
2019-08-24 11:09:34,541 INFO : Microblog startup [in D:\ThunderDownload\Python_code\venv_test\app\__init__.py:42]
2019-08-24 11:16:32,761 INFO : Microblog startup [in D:\ThunderDownload\Python_code\venv_test\app\__init__.py:42]
2019-08-24 11:27:51,020 INFO : Microblog startup [in D:\ThunderDownload\Python_code\venv_test\app\__init__.py:44]
2019-08-24 12:55:33,460 INFO : Microblog startup [in D:\ThunderDownload\Python_code\venv_test\app\__init__.py:44]
2019-08-24 12:56:40,012 INFO : Microblog startup [in D:\ThunderDownload\Python_code\venv_test\app\__init__.py:44]
2019-08-24 13:18:04,882 INFO : Microblog startup [in D:\ThunderDownload\Python_code\venv_test\app\__init__.py:46]
2019-08-24 15:11:20,922 INFO : Microblog startup [in D:\ThunderDownload\Python_code\venv_test\app\__init__.py:46]
